## try-catch와 에러 헨들링

**`try...catch`** 문은 실행할 코드블럭을 표시하고 예외(exception)가 발생(throw)할 경우의 응답을 지정합니다.

### 1.문법

```js
try {
  try_statements //코드
}
[catch (exception_var) {
  catch_statements //에러 헨들링
}]
[finally {
  finally_statements // 에러 발생 여부와 상관없이 try/catch 이후에 실행됨
}]
```

try…catch 동작 알고리즘은 다음과 같습니다.

1. 먼저, `try {...}` 안의 코드가 실행됩니다.
2. 에러가 없다면, `try` 안의 마지막 줄까지 실행되고, `catch` 블록은 건너뜁니다.
3. 에러가 있다면, `try` 안 코드의 실행이 중단되고, `catch(err)` 블록으로 제어 흐름이 넘어갑니다. 변수 `err`(아무 이름이나 사용 가능)는 무슨 일이 일어났는지에 대한 설명이 담긴 에러 객체를 포함합니다.
4. try 선언이 완료된 이후에 실행된 선언들. 이 선언들은 예외 발생 여부와 상관없이 실행됩니다.

### 2. 특징

#### 1). 런타임 에러에만 작동한다.

`try..catch`는 실행 가능한(runnable) 코드에만 동작합니다. 실행 가능한 코드는 유효한 자바스크립트 코드를 의미합니다.

중괄호 짝이 안 맞는 것처럼 코드가 문법적으로 잘못된 경우엔 `try..catch`가 동작하지 않습니다.

```javascript
try {
  {{{{{{{{{{{{
} catch(e) {
  alert("유효하지 않은 코드이기 때문에, 자바스크립트 엔진은 이 코드를 이해할 수 없습니다.");
}
```

자바스크립트 엔진은 코드를 읽고 난 후 코드를 실행합니다. 코드를 읽는 중에 발생하는 에러는 'parse-time 에러’라고 부르는데, 엔진은 이 코드를 이해할 수 없기 때문에 parse-time 에러는 코드 안에서 복구가 불가능합니다.

`try..catch`는 유효한 코드에서 발생하는 에러만 처리할 수 있습니다. 이런 에러를 ‘런타임 에러(runtime error)’ 혹은 '예외(exception)'라고 부릅니다.

#### 2). `try..catch`**는 동기적으로 동작합니다.**

setTimeout처럼 ‘스케줄 된(scheduled)’ 코드에서 발생한 예외는 `try..catch`에서 잡아낼 수 없습니다.

```javascript
try {
  setTimeout(function() {
    noSuchVariable; // 스크립트는 여기서 죽습니다.
  }, 1000);
} catch (e) {
  alert( "작동 멈춤" );
}
```

`setTimeout`에 넘겨진 익명 함수는 엔진이 `try..catch`를 떠난 다음에서야 실행되기 때문입니다.

스케줄 된 함수 내부의 예외를 잡으려면, `try..catch`를 반드시 함수 내부에 구현해야 합니다.

```javascript
setTimeout(function() {
  try {
    noSuchVariable; // 이제 try..catch에서 에러를 핸들링 할 수 있습니다!
  } catch {
    alert( "에러를 잡았습니다!" );
  }
}, 1000);
```

### 3. throw 연산자

#### 1).문법

```js
throw <error object>
```

이론적으로는 숫자, 문자열 같은 원시형 자료를 포함한 어떤 것이든 에러 객체(error object)로 사용할 수 있습니다. 하지만 내장 에러와의 호환을 위해 되도록 에러 객체에 `name`과 `message` 프로퍼티를 넣어주는 것을 권장합니다.

자바스크립트는 `Error`, `SyntaxError`, `ReferenceError`, `TypeError`등의 표준 에러 객체 관련 생성자를 지원합니다. 이 생성자들을 이용해 에러 객체를 만들 수도 있습니다.

```js
let error = new Error(message);
// or
let error = new SyntaxError(message);
let error = new ReferenceError(message);

//예제
let error = new Error("이상한 일이 발생했습니다. o_O");

alert(error.name); // Error
alert(error.message); // 이상한 일이 발생했습니다. o_O
```

### 2).throw에러를 사용 할때

`catch`는 원래 `try` 블록에서 발생한 *모든* 에러를 잡으려는 목적으로 만들어졌습니다. 

**catch는 알고 있는 에러만 처리하고 나머지는 ‘다시 던져야’ 합니다.**

1. catch가 모든 에러를 받습니다.
2. `catch(err) {...}` 블록 안에서 에러 객체 `err`를 분석합니다.
3. 에러 처리 방법을 알지 못하면 `throw err`를 합니다.

혹은 제어가 try 블록에서 catch 블록으로 자동 전송되기 전에 6 가지 유형의 오류 중 하나가 발생할 때까지 기다리지 않고 필요에 따라 발생하도록 강제로 자신의 예외를 명시 적으로 던질 수도 있습니다. 이는 오류가 무엇인지, 언제 제어를 전달해야하는지에 대한 고유 한 정의를 작성하는 데 유용합니다.

| Error Name     | Description                           |
| :------------- | :------------------------------------ |
| EvalError      | eval() 함수에서 오류가 발생했습니다.  |
| RangeError     | 범위를 벗어난 숫자 값이 발생했습니다. |
| ReferenceError | 잘못된 참조가 발생했습니다.           |
| SyntaxError    | 구문 오류가 발생했습니다              |
| TypeError      | type 오류가 발생했습니다              |
| URIError       | encodeURI()에서 오류가 발생했습니다   |

### 4.error object

JavaScript에는 오류가 발생할 때 오류 정보를 제공하는 내장 오류 객체가 있습니다.

error 객체는 name과 message라는 두 가지 유용한 속성을 제공합니다.

| Property | Description                                  |
| :------- | :------------------------------------------- |
| name     | 오류 이름을 설정하거나 반환합니다.           |
| message  | 오류 메시지(문자열)를 설정하거나 반환합니다. |

